<mujocoinclude>
    <body name="base_link" pos="0.00000000 0.00000000 0.00000000" quat="1 0 0 0">
      <geom name="base_link_collision" pos="0 0 0" quat="1.0 0.0 0.0 0.0" type="mesh" mesh="base_link_mesh"  class="collision"/>
      <geom name="base_link_visual" pos="0 0 0" quat="1.0 0.0 0.0 0.0" material="LightGrey" type="mesh" mesh="base_link_mesh" class="visual" />
      <body name="arm_1_link" pos="0 0 0.14" quat="-3.673205103346574e-06 0.9999999999932537 0.0 -0.0">
        <joint name="arm_1_joint" type="hinge" ref="0.0" range="-2.094 2.094" axis="0 0 1" damping="2.0"/>
        <site name="arm_1_joint_site" pos="0 0 0" quat="1 0 0 0" />
        <inertial pos="-0.000117276290344319 0.0122228931530341 -0.0624701032538624" quat="1.0 0.0 0.0 0.0" mass="0.139955029249829" diaginertia="0.000325457683704532 0.000236310540102376 0.000149250424678437" />
        <geom name="arm_1_link_collision" pos="0 0 0" quat="1.0 0.0 0.0 0.0" type="mesh" mesh="arm_1_link_mesh" class="collision" />
        <geom name="arm_1_link_visual" pos="0 0 0" quat="1.0 0.0 0.0 0.0" material="" type="mesh" mesh="arm_1_link_mesh" class="visual" />
        <body name="arm_2_link" pos="0 0 -0.095" quat="0.7071054825112363 -0.7071080798594735 0.0 0.0">
          <joint name="arm_2_joint" type="hinge" ref="0.0" range="-2.094 1.5707963267948966" axis="0 0 1" damping="2.0" />
          <site name="arm_2_joint_site" pos="0 0 0" quat="1 0 0 0" />
          <inertial pos="-0.0174680236422027 0.0906428723777263 -3.29773055841057E-07" quat="1.0 0.0 0.0 0.0" mass="0.169587438537964" diaginertia="0.000621052722745594 0.000313103181930873 0.000405564215148294" />
          <geom name="arm_2_link_collision" pos="0 0 0" quat="1.0 0.0 0.0 0.0" type="mesh" mesh="arm_2_link_mesh" class="collision" />
          <geom name="arm_2_link_visual" pos="0 0 0" quat="1.0 0.0 0.0 0.0" material="" type="mesh" mesh="arm_2_link_mesh" class="visual" />
          <body name="arm_3_link" pos="-0.018 0.145 0" quat="0.7071054825112363 0.7071080798594735 0.0 0.0">
            <joint name="arm_3_joint" type="hinge" ref="0.0" range="-2.793 2.793" axis="0 0 1" damping="2.0"/>
            <site name="arm_3_joint_site" pos="0 0 0" quat="1 0 0 0" />
            <inertial pos="-0.000485421157864062 6.83606345788855E-05 -0.0518192203685102" quat="1.0 0.0 0.0 0.0" mass="0.113439004135591" diaginertia="0.000235493816702144 0.00016178376053715 0.000115808035506604" />
            <geom name="arm_3_link_collision" pos="0 0 0" quat="1.0 0.0 0.0 0.0" type="mesh" mesh="arm_3_link_mesh" class="collision" />
            <geom name="arm_3_link_visual" pos="0 0 0" quat="1.0 0.0 0.0 0.0" material="" type="mesh" mesh="arm_3_link_mesh" class="visual" />
            <body name="arm_4_link" pos="0 0 -0.105" quat="0.7071054825112363 -0.7071080798594735 0.0 0.0">
              <joint name="arm_4_joint" type="hinge" ref="0.0" range="-1.92 1.92" axis="0 0 1" damping="2.0"/>
              <site name="arm_4_joint_site" pos="0 0 0" quat="1 0 0 0" />
              <inertial pos="-0.000523676254705792 0.0548426547509552 -2.32870051976362E-06" quat="1.0 0.0 0.0 0.0" mass="0.0923387760232059" diaginertia="0.000210731589973129 0.000113562778686391 0.000125255151693492" />
              <geom name="arm_4_link_collision" pos="0 0 0" quat="1.0 0.0 0.0 0.0" type="mesh" mesh="arm_4_link_mesh" class="collision" />
              <geom name="arm_4_link_visual" pos="0 0 0" quat="1.0 0.0 0.0 0.0" material="" type="mesh" mesh="arm_4_link_mesh" class="visual" />
              <body name="arm_5_link" pos="0 0.105 0" quat="0.7071054825112363 0.7071080798594735 0.0 0.0">
                <joint name="arm_5_joint" type="hinge" ref="0.0" range="-2.793 2.793" axis="0 0 1" damping="2.0"/>
                <site name="arm_5_joint_site" pos="0 0 0" quat="1 0 0 0" />
                <inertial pos="-0.000318440471593399 -4.33257243015121E-09 -0.0421503668391696" quat="1.0 0.0 0.0 0.0" mass="0.0467464068633803" diaginertia="5.04548630748624e-05 3.77221825095438e-05 2.16144252369209e-05" />
                <geom name="arm_5_link_collision" pos="0 0 0" quat="1.0 0.0 0.0 0.0" type="mesh" mesh="arm_5_link_mesh" class="collision" />
                <geom name="arm_5_link_visual" pos="0 0 0" quat="1.0 0.0 0.0 0.0" material="" type="mesh" mesh="arm_5_link_mesh" class="visual" />
                <body name="arm_6_link" pos="0 -0.0002 -0.075" quat="0.7071054825112363 -0.7071080798594735 0.0 0.0">
                  <joint name="arm_6_joint" type="hinge" ref="0.0" range="-1.57 1.57" axis="0 0 1" damping="2.0"/>
                  <site name="arm_6_joint_site" pos="0 0 0" quat="1 0 0 0" />
                  <inertial pos="0.00023077781229322 0.0477776544969339 -0.000274578550932736" quat="1.0 0.0 0.0 0.0" mass="0.0663534128705839" diaginertia="4.46094691893757e-05 3.14288652751225e-05 5.02053835003699e-05" />
                  <geom name="arm_6_link_collision" pos="0 0 0" quat="1.0 0.0 0.0 0.0" type="mesh" mesh="arm_6_link_mesh" class="collision" />
                  <geom name="arm_6_link_visual" pos="0 0 0" quat="1.0 0.0 0.0 0.0" material="" type="mesh" mesh="arm_6_link_mesh" class="visual" />
                  <body name="gripper_1_link" pos="-0.0001 0.06175 0.0115" quat="0.4999981633974483 0.49999999999662686 0.5000018366025516 0.49999999999662686">
                    <joint name="gripper_1_joint" type="hinge" ref="0.0" range="0 0.698" axis="0 0 1" damping="2.0"/>
                    <site name="gripper_1_joint_site" pos="0 0 0" quat="1 0 0 0" />
                    <inertial pos="0.0428524050252714 0.0102173668833365 1.53174098056555E-05" quat="1.0 0.0 0.0 0.0" mass="0.0229460702572688" diaginertia="1.29555143093886e-05 2.6397024313168e-05 1.7220072843041e-05" />
                    <geom name="gripper_1_link_collision" pos="0 0 0" quat="1.0 0.0 0.0 0.0" type="mesh" mesh="gripper_1_link_mesh" class="collision" />
                    <geom name="gripper_1_link_visual" pos="0 0 0" quat="1.0 0.0 0.0 0.0" material="" type="mesh" mesh="gripper_1_link_mesh" class="visual" />
                  </body>
                  <body name="gripper_2_link" pos="-0.0001 0.06175 -0.012" quat="0.4999981633974483 -0.49999999999662686 -0.5000018366025516 0.49999999999662686">
                    <joint name="gripper_2_joint" type="hinge" ref="0.0" range="0 0.698" axis="0 0 1" damping="2.0"/>
                    <site name="gripper_2_joint_site" pos="0 0 0" quat="1 0 0 0" />
                    <inertial pos="0.0428304976382079 0.0102055784464402 9.00813000661443E-07" quat="1.0 0.0 0.0 0.0" mass="0.0229585233092397" diaginertia="1.30784892266813e-05 2.67601282938736e-05 1.74955869845825e-05" />
                    <geom name="gripper_2_link_collision" pos="0 0 0" quat="1.0 0.0 0.0 0.0" type="mesh" mesh="gripper_1_link_mesh" class="collision" />
                    <geom name="gripper_2_link_visual" pos="0 0 0" quat="1.0 0.0 0.0 0.0" material="" type="mesh" mesh="gripper_1_link_mesh" class="visual" />
                  </body>
                  <body name="gripper_centor_link" pos="-0.000 0.125 0" quat="0.4999981633974483 -0.49999999999662686 -0.5000018366025516 0.49999999999662686" />
                </body>
              </body>
            </body>
          </body>
        </body>
      </body>
      <site name="base_link_site" pos="0 0 0" quat="1 0 0 0" />
      <camera name="front_camera" mode="track" fovy="90.0" quat="4.329780281177467e-17 4.329780281177466e-17 0.7071067811865475 0.7071067811865476" pos="0.0 2.0 0.5" />
      <camera name="side_camera" mode="track" fovy="90.0" quat="-0.5 -0.4999999999999999 0.5 0.5000000000000001" pos="-2.0 0.0 0.5" />
    </body>

</mujocoinclude>